Workbook
Name SegmentaciónDeDatos_Estado: #N/A
Name SegmentaciónDeDatos_Estado1: #N/A
Name SegmentaciónDeDatos_Provincia: #N/A
Name SegmentaciónDeDatos_Tipo_Combustible: #N/A

Sheet Proyecto
A1: Campo | B1: Descripción
A2: Título del proyecto | B2: Análisis de la oferta y ventas de autos en la Feria del Automóvil
A3: Descripción | B3: Se realiza un análisis exploratorio de los autos ofrecidos y vendidos en la feria, para identificar patrones de precios, marcas más frecuentes y tipos de combustible más comunes.
A4: Autora | B4: María Luján Massironi
A5: Programa académico | B5: Diplomatura en Data Science – Coderhouse
A6: Objetivo principal | B6: Detectar tendencias de mercado en base al tipo de vehículo, precio y características.
A7: Fuente de datos | B7: Dataset simulado coherente con publicaciones reales.
A8: Estructura | B8: 40 observaciones, 17 columnas.

Sheet Base_Cruda
A1: Esta es la base de datos cruda original, antes del proceso de limpieza y normalización.
A2: ID_Auto | B2: Marca | C2: Modelo | D2: Año | E2: Kilometraje | F2: Precio_ARS | G2: Tipo_Combustible | H2: Transmisión | I2: Color | J2: Puertas | K2: Carrocería | L2: Provincia | M2: Fecha_Publicación | N2: Estado | O2: Origen | P2: Financiación
A3: 1 | B3: Citroën | C3: Berlingo | D3: 2018 | E3: 140300 | F3: 4392397 | G3: Híbrido | H3: Automática | I3: Rojo | J3: 3 | K3: Sedán | L3: Mendoza | M3: 2023-08-04 | N3: Seminuevo | O3: Importado | P3: No
A4: 2 | B4: Renault | C4: Kwid | D4: 2016 | E4: 44429 | F4: 15550583 | G4: Nafta | H4: Automática | I4: Plateado | J4: 5 | K4: Sedán | L4: Santa Fe | M4: 2025-03-02 | N4: Seminuevo | O4: Importado | P4: Sí
A5: 3 | B5: Ford | C5: Fiesta | D5: 2020 | E5: 118020 | F5: 18134749 | G5: Nafta | H5: Automática | I5: Azul | J5: 3 | K5: SUV | L5: Córdoba | M5: 2023-11-26 | N5: Excelente | O5: Nacional | P5: No
A6: 4 | B6: Peugeot | C6: 208 | D6: 2017 | E6: 28856 | F6: 21316848 | G6: Híbrido | H6: Automática | I6: Gris | J6: 5 | K6: Pickup | L6: Entre Ríos | M6: 2024-03-23 | N6: Excelente | O6: Importado | P6: No
A7: 5 | B7: Honda | C7: Fit | D7: 2017 | E7: 137684 | F7: 22243508 | G7: Nafta | H7: Manual | I7: Rojo | J7: 4 | K7: Pickup | L7: Santa Fe | M7: 2025-10-05 | N7: Seminuevo | O7: Nacional | P7: Sí
A8: 6 | B8: Peugeot | C8: 2008 | D8: 2022 | E8: 25965 | F8: 7701714 | G8: Híbrido | H8: Manual | I8: Gris | J8: 3 | K8: SUV | L8: Santa Fe | M8: 2023-10-16 | N8: Excelente | O8: Nacional | P8: No
A9: 7 | B9: Fiat | C9: Argo | D9: 2017 | E9: 44801 | F9: 13727866 | G9: Híbrido | H9: Automática | I9: Plateado | J9: 5 | K9: SUV | L9: Santa Fe | M9: 2023-10-07 | N9: Usado | O9: Nacional | P9: Sí
A10: 8 | B10: Peugeot | C10: 208 | D10: 2015 | E10: 125599 | F10: 19200946 | G10: Diésel | H10: Manual | I10: Azul | J10: 3 | K10: Hatchback | L10: Entre Ríos | M10: 2023-09-19 | N10: Excelente | O10: Importado | P10: Sí
A11: 9 | B11: Ford | C11: Ranger | D11: 2021 | E11: 70467 | F11: 21908286 | G11: Nafta | H11: Manual | I11: Blanco | J11: 3 | K11: Sedán | L11: Mendoza | M11: 2024-01-04 | N11: Usado | O11: Nacional | P11: No
A12: 10 | B12: Toyota | C12: Yaris | D12: 2017 | E12: 52055 | F12: 23237584 | G12: Híbrido | H12: Manual | I12: Plateado | J12: 5 | K12: Pickup | L12: Córdoba | M12: 2023-10-18 | N12: Seminuevo | O12: Nacional | P12: No
A13: 11 | B13: Honda | C13: Civic | D13: 2023 | E13: 82137 | F13: 23025850 | G13: Diésel | H13: Manual | I13: Azul | J13: 3 | K13: Sedán | L13: Entre Ríos | M13: 2025-08-22 | N13: Usado | O13: Nacional | P13: Sí
A14: 12 | B14: Fiat | C14: Toro | D14: 2015 | E14: 77417 | F14: 20319193 | G14: Diésel | H14: Automática | I14: Plateado | J14: 3 | K14: Pickup | L14: Santa Fe | M14: 2023-11-11 | N14: Usado | O14: Nacional | P14: Sí
... A42: 40 | B42: Volkswagen | C42: Amarok | D42: 2019 | E42: 141731 | F42: 18938963 | G42: Nafta | H42: Manual | I42: Blanco | J42: 3 | K42: Sedán | L42: Buenos Aires | M42: 2024-05-05 | N42: Excelente | O42: Nacional | P42: No

Sheet Data_autos
A1: ID_Auto | B1: Marca | C1: Modelo | D1: Año | E1: Kilometraje | F1: Precio_ARS | G1: Tipo_Combustible | H1: Transmisión | I1: Color | J1: Puertas | K1: Carrocería | L1: Provincia | M1: Fecha_Publicación | N1: Estado | O1: Origen | P1: Financiación | Q1: Precio_Nivel | R1: Es_Nacional | S1: Mes | T1: Antigüedad (años) | U1: Segmento_KM | V1: Precio_USD
A2: 1 | B2: Citroën | C2: Berlingo | D2: 2018 | E2: 140300 | F2: 4392397 | G2: Híbrido | H2: Automática | I2: Rojo | J2: 3 | K2: Sedán | L2: Mendoza | M2: 2023-08-04 | N2: Seminuevo | O2: Importado | P2: No | Q2: =IF(F2>20000000,"Alta","Media") -> Media | R2: =IF(O2="Nacional","Sí","No") -> No | S2: =DATE(YEAR(M2),MONTH(M2),1) -> 45139 | T2: =YEAR(TODAY())-D2 -> 7 | U2: =IF(E2>Parametros!$B$5,"Alto",IF(E2>Parametros!$B$4,"Medio","Bajo")) -> Alto | V2: =F2/Parametros!$B$2 -> 3993.0882
A3: 2 | B3: Renault | C3: Kwid | D3: 2016 | E3: 44429 | F3: 15550583 | G3: Nafta | H3: Automática | I3: Plateado | J3: 5 | K3: Sedán | L3: Santa Fe | M3: 2025-03-02 | N3: Seminuevo | O3: Importado | P3: Sí | Q3: =IF(F3>20000000,"Alta","Media") -> Media | R3: =IF(O3="Nacional","Sí","No") -> No | S3: =DATE(YEAR(M3),MONTH(M3),1) -> 45717 | T3: =YEAR(TODAY())-D3 -> 9 | U3: =IF(E3>Parametros!$B$5,"Alto",IF(E3>Parametros!$B$4,"Medio","Bajo")) -> Bajo | V3: =F3/Parametros!$B$2 -> 14136.894
A4: 3 | B4: Ford | C4: Fiesta | D4: 2020 | E4: 118020 | F4: 18134749 | G4: Nafta | H4: Automática | I4: Azul | J4: 3 | K4: SUV | L4: Córdoba | M4: 2023-11-26 | N4: Excelente | O4: Nacional | P4: No | Q4: =IF(F4>20000000,"Alta","Media") -> Media | R4: =IF(O4="Nacional","Sí","No") -> Sí | S4: =DATE(YEAR(M4),MONTH(M4),1) -> 45231 | T4: =YEAR(TODAY())-D4 -> 5 | U4: =IF(E4>Parametros!$B$5,"Alto",IF(E4>Parametros!$B$4,"Medio","Bajo")) -> Alto | V4: =F4/Parametros!$B$2 -> 16486.135
A5: 4 | B5: Peugeot | C5: 208 | D5: 2017 | E5: 28856 | F5: 21316848 | G5: Híbrido | H5: Automática | I5: Gris | J5: 5 | K5: Pickup | L5: Entre Ríos | M5: 2024-03-23 | N5: Excelente | O5: Importado | P5: No | Q5: =IF(F5>20000000,"Alta","Media") -> Alta | R5: =IF(O5="Nacional","Sí","No") -> No | S5: =DATE(YEAR(M5),MONTH(M5),1) -> 45352 | T5: =YEAR(TODAY())-D5 -> 8 | U5: =IF(E5>Parametros!$B$5,"Alto",IF(E5>Parametros!$B$4,"Medio","Bajo")) -> Bajo | V5: =F5/Parametros!$B$2 -> 19378.953
A6: 5 | B6: Honda | C6: Fit | D6: 2017 | E6: 137684 | F6: 22243508 | G6: Nafta | H6: Manual | I6: Rojo | J6: 4 | K6: Pickup | L6: Santa Fe | M6: 2025-10-05 | N6: Seminuevo | O6: Nacional | P6: Sí | Q6: =IF(F6>20000000,"Alta","Media") -> Alta | R6: =IF(O6="Nacional","Sí","No") -> Sí | S6: =DATE(YEAR(M6),MONTH(M6),1) -> 45931 | T6: =YEAR(TODAY())-D6 -> 8 | U6: =IF(E6>Parametros!$B$5,"Alto",IF(E6>Parametros!$B$4,"Medio","Bajo")) -> Alto | V6: =F6/Parametros!$B$2 -> 20221.371
A7: 6 | B7: Peugeot | C7: 2008 | D7: 2022 | E7: 25965 | F7: 7701714 | G7: Híbrido | H7: Manual | I7: Gris | J7: 3 | K7: SUV | L7: Santa Fe | M7: 2023-10-16 | N7: Excelente | O7: Nacional | P7: No | Q7: =IF(F7>20000000,"Alta","Media") -> Media | R7: =IF(O7="Nacional","Sí","No") -> Sí | S7: =DATE(YEAR(M7),MONTH(M7),1) -> 45200 | T7: =YEAR(TODAY())-D7 -> 3 | U7: =IF(E7>Parametros!$B$5,"Alto",IF(E7>Parametros!$B$4,"Medio","Bajo")) -> Bajo | V7: =F7/Parametros!$B$2 -> 7001.5582
A8: 7 | B8: Fiat | C8: Argo | D8: 2017 | E8: 44801 | F8: 13727866 | G8: Híbrido | H8: Automática | I8: Plateado | J8: 5 | K8: SUV | L8: Santa Fe | M8: 2023-10-07 | N8: Usado | O8: Nacional | P8: Sí | Q8: =IF(F8>20000000,"Alta","Media") -> Media | R8: =IF(O8="Nacional","Sí","No") -> Sí | S8: =DATE(YEAR(M8),MONTH(M8),1) -> 45200 | T8: =YEAR(TODAY())-D8 -> 8 | U8: =IF(E8>Parametros!$B$5,"Alto",IF(E8>Parametros!$B$4,"Medio","Bajo")) -> Bajo | V8: =F8/Parametros!$B$2 -> 12479.878
A9: 8 | B9: Peugeot | C9: 208 | D9: 2015 | E9: 125599 | F9: 19200946 | G9: Diésel | H9: Manual | I9: Azul | J9: 3 | K9: Hatchback | L9: Entre Ríos | M9: 2023-09-19 | N9: Excelente | O9: Importado | P9: Sí | Q9: =IF(F9>20000000,"Alta","Media") -> Media | R9: =IF(O9="Nacional","Sí","No") -> No | S9: =DATE(YEAR(M9),MONTH(M9),1) -> 45170 | T9: =YEAR(TODAY())-D9 -> 10 | U9: =IF(E9>Parametros!$B$5,"Alto",IF(E9>Parametros!$B$4,"Medio","Bajo")) -> Alto | V9: =F9/Parametros!$B$2 -> 17455.405
A10: 9 | B10: Ford | C10: Ranger | D10: 2021 | E10: 70467 | F10: 21908286 | G10: Nafta | H10: Manual | I10: Blanco | J10: 3 | K10: Sedán | L10: Mendoza | M10: 2024-01-04 | N10: Usado | O10: Nacional | P10: No | Q10: =IF(F10>20000000,"Alta","Media") -> Alta | R10: =IF(O10="Nacional","Sí","No") -> Sí | S10: =DATE(YEAR(M10),MONTH(M10),1) -> 45292 | T10: =YEAR(TODAY())-D10 -> 4 | U10: =IF(E10>Parametros!$B$5,"Alto",IF(E10>Parametros!$B$4,"Medio","Bajo")) -> Medio | V10: =F10/Parametros!$B$2 -> 19916.624
A11: 10 | B11: Toyota | C11: Yaris | D11: 2017 | E11: 52055 | F11: 23237584 | G11: Híbrido | H11: Manual | I11: Plateado | J11: 5 | K11: Pickup | L11: Córdoba | M11: 2023-10-18 | N11: Seminuevo | O11: Nacional | P11: No | Q11: =IF(F11>20000000,"Alta","Media") -> Alta | R11: =IF(O11="Nacional","Sí","No") -> Sí | S11: =DATE(YEAR(M11),MONTH(M11),1) -> 45200 | T11: =YEAR(TODAY())-D11 -> 8 | U11: =IF(E11>Parametros!$B$5,"Alto",IF(E11>Parametros!$B$4,"Medio","Bajo")) -> Medio | V11: =F11/Parametros!$B$2 -> 21125.076
A12: 11 | B12: Honda | C12: Civic | D12: 2023 | E12: 82137 | F12: 23025850 | G12: Diésel | H12: Manual | I12: Azul | J12: 3 | K12: Sedán | L12: Entre Ríos | M12: 2025-08-22 | N12: Usado | O12: Nacional | P12: Sí | Q12: =IF(F12>20000000,"Alta","Media") -> Alta | R12: =IF(O12="Nacional","Sí","No") -> Sí | S12: =DATE(YEAR(M12),MONTH(M12),1) -> 45870 | T12: =YEAR(TODAY())-D12 -> 2 | U12: =IF(E12>Parametros!$B$5,"Alto",IF(E12>Parametros!$B$4,"Medio","Bajo")) -> Medio | V12: =F12/Parametros!$B$2 -> 20932.591
A13: 12 | B13: Fiat | C13: Toro | D13: 2015 | E13: 77417 | F13: 20319193 | G13: Diésel | H13: Automática | I13: Plateado | J13: 3 | K13: Pickup | L13: Santa Fe | M13: 2023-11-11 | N13: Usado | O13: Nacional | P13: Sí | Q13: =IF(F13>20000000,"Alta","Media") -> Alta | R13: =IF(O13="Nacional","Sí","No") -> Sí | S13: =DATE(YEAR(M13),MONTH(M13),1) -> 45231 | T13: =YEAR(TODAY())-D13 -> 10 | U13: =IF(E13>Parametros!$B$5,"Alto",IF(E13>Parametros!$B$4,"Medio","Bajo")) -> Medio | V13: =F13/Parametros!$B$2 -> 18471.994
... A41: 40 | B41: Volkswagen | C41: Amarok | D41: 2019 | E41: 141731 | F41: 18938963 | G41: Nafta | H41: Manual | I41: Blanco | J41: 3 | K41: Sedán | L41: Buenos Aires | M41: 2024-05-05 | N41: Excelente | O41: Nacional | P41: No | Q41: =IF(F41>20000000,"Alta","Media") -> Media | R41: =IF(O41="Nacional","Sí","No") -> Sí | S41: =DATE(YEAR(M41),MONTH(M41),1) -> 45413 | T41: =YEAR(TODAY())-D41 -> 6 | U41: =IF(E41>Parametros!$B$5,"Alto",IF(E41>Parametros!$B$4,"Medio","Bajo")) -> Alto | V41: =F41/Parametros!$B$2 -> 17217.239

Sheet Parametros
A1: Parámetro | B1: Valor
A2: Tipo_cambio_ARS_USD | B2: 1100
A3: Umbral_Precio_Alta | B3: 20000000
A4: Umbral_KM_Medio | B4: 50000
A5: Umbral_KM_Alto | B5: 100000

Sheet Analisis
A1: ¿Cuántos autos hay por marca? | E1: ¿Cuál es el precio promedio por marca?
A2: Usar CONTAR.SI sobre la columna Marca (B). | E2: Usar PROMEDIO.SI con columna Precio_ARS.
A4: Marca | B4: Cantidad | F4: Precio promedio (ARS)
A5: Citroën | B5: =COUNTIF(Data_autos!B:B, A5) -> 2 | F5: =AVERAGEIF(Data_autos!B:B, A5, Data_autos!F:F) -> 4392397
A6: Renault | B6: =COUNTIF(Data_autos!B:B, A6) -> 6 | F6: =AVERAGEIF(Data_autos!B:B, A6, Data_autos!F:F) -> 18657438
A7: Ford | B7: =COUNTIF(Data_autos!B:B, A7) -> 6 | F7: =AVERAGEIF(Data_autos!B:B, A7, Data_autos!F:F) -> 16033651
A8: Peugeot | B8: =COUNTIF(Data_autos!B:B, A8) -> 8 | F8: =AVERAGEIF(Data_autos!B:B, A8, Data_autos!F:F) -> 17399182
A9: Honda | B9: =COUNTIF(Data_autos!B:B, A9) -> 6 | F9: =AVERAGEIF(Data_autos!B:B, A9, Data_autos!F:F) -> 17842625
A10: Fiat | B10: =COUNTIF(Data_autos!B:B, A10) -> 4 | F10: =AVERAGEIF(Data_autos!B:B, A10, Data_autos!F:F) -> 17023530
A11: Volkswagen | B11: =COUNTIF(Data_autos!B:B, A11) -> 4 | F11: =AVERAGEIF(Data_autos!B:B, A11, Data_autos!F:F) -> 11735898
A12: Toyota | B12: =COUNTIF(Data_autos!B:B, A12) -> 2 | F12: =AVERAGEIF(Data_autos!B:B, A12, Data_autos!F:F) -> 23237584
A13: Chevrolet | B13: =COUNTIF(Data_autos!B:B, A13) -> 2 | F13: =AVERAGEIF(Data_autos!B:B, A13, Data_autos!F:F) -> 10016668
A17: ¿Qué porcentaje tiene financiación? | E17: ¿Cuántos autos ofrecen financiación?
A18: Usar fórmula =F2/F4 en tabla de financiación. | E18: Usar CONTAR.SI en columna Financiación (Q).
A19: Provincia | B19: Cantidad de Autos | E19: TOTAL DE AUTOS: | F19: =SUM(E21,E23) -> 40
A20: Buenos Aires | B20: =COUNTIF(Data_autos!L:L,A20) -> 4 | E20: Con financiación | F20: % Con financiación
A21: Córdoba | B21: =COUNTIF(Data_autos!L:L,A21) -> 6 | E21: =COUNTIF(Data_autos!P:P,"Sí") -> 20 | F21: =E21/F19 -> 0.5
A22: Mendoza | B22: =COUNTIF(Data_autos!L:L,A22) -> 12 | E22: Sin financiación | F22: % Sin financiación
A23: Santa Fe | B23: =COUNTIF(Data_autos!L:L,A23) -> 12 | E23: =COUNTIF(Data_autos!P:P,"No") -> 20 | F23: =E23/F19 -> 0.5
A24: Entre Ríos | B24: =COUNTIF(Data_autos!L:L,A24) -> 6
A29: ¿Qué tipo de combustible es más común?
A30: Usar CONTAR.SI en columna Tipo_Combustible (G).
A31: Tipo de combustible | B31: Cantidad | C31: Precio promedio (ARS)
A32: Nafta | B32: =COUNTIF(Data_autos!G:G, A32) -> 16 | C32: =AVERAGEIF(Data_autos!G:G, A32, Data_autos!F:F) -> 16011685
A33: Diésel | B33: =COUNTIF(Data_autos!G:G, A33) -> 8 | C33: =AVERAGEIF(Data_autos!G:G, A33, Data_autos!F:F) -> 18140664
A34: Híbrido | B34: =COUNTIF(Data_autos!G:G, A34) -> 16 | C34: =AVERAGEIF(Data_autos!G:G, A34, Data_autos!F:F) -> 15213404
A36: Pregunta avanzada: tendencia de publicaciones por mes
A37: Se agrupa por Mes (columna 'Mes' creada en Data_autos) y se calcula cantidad y precio promedio.
A39: Mes | B39: Cantidad publicaciones | C39: Precio promedio (ARS)
A40: 2023-03 | B40: =COUNTIF(Data_autos!$S:$S,DATE(LEFT(A40,4),MID(A40,6,2),1)) -> 2 | C40: =AVERAGEIF(Data_autos!$S:$S,DATE(LEFT(A40,4),MID(A40,6,2),1),Data_autos!$F:$F) -> 4532832
A41: 2023-06 | B41: =COUNTIF(Data_autos!$S:$S,DATE(LEFT(A41,4),MID(A41,6,2),1)) -> 2 | C41: =AVERAGEIF(Data_autos!$S:$S,DATE(LEFT(A41,4),MID(A41,6,2),1),Data_autos!$F:$F) -> 8258517
A42: 2023-08 | B42: =COUNTIF(Data_autos!$S:$S,DATE(LEFT(A42,4),MID(A42,6,2),1)) -> 6 | C42: =AVERAGEIF(Data_autos!$S:$S,DATE(LEFT(A42,4),MID(A42,6,2),1),Data_autos!$F:$F) -> 14765221
A43: 2023-09 | B43: =COUNTIF(Data_autos!$S:$S,DATE(LEFT(A43,4),MID(A43,6,2),1)) -> 2 | C43: =AVERAGEIF(Data_autos!$S:$S,DATE(LEFT(A43,4),MID(A43,6,2),1),Data_autos!$F:$F) -> 19200946
A44: 2023-10 | B44: =COUNTIF(Data_autos!$S:$S,DATE(LEFT(A44,4),MID(A44,6,2),1)) -> 6 | C44: =AVERAGEIF(Data_autos!$S:$S,DATE(LEFT(A44,4),MID(A44,6,2),1),Data_autos!$F:$F) -> 14889055
A45: 2023-11 | B45: =COUNTIF(Data_autos!$S:$S,DATE(LEFT(A45,4),MID(A45,6,2),1)) -> 4 | C45: =AVERAGEIF(Data_autos!$S:$S,DATE(LEFT(A45,4),MID(A45,6,2),1),Data_autos!$F:$F) -> 19226971
A46: 2024-01 | B46: =COUNTIF(Data_autos!$S:$S,DATE(LEFT(A46,4),MID(A46,6,2),1)) -> 2 | C46: =AVERAGEIF(Data_autos!$S:$S,DATE(LEFT(A46,4),MID(A46,6,2),1),Data_autos!$F:$F) -> 21908286
A47: 2024-03 | B47: =COUNTIF(Data_autos!$S:$S,DATE(LEFT(A47,4),MID(A47,6,2),1)) -> 4 | C47: =AVERAGEIF(Data_autos!$S:$S,DATE(LEFT(A47,4),MID(A47,6,2),1),Data_autos!$F:$F) -> 21606268
A48: 2024-05 | B48: =COUNTIF(Data_autos!$S:$S,DATE(LEFT(A48,4),MID(A48,6,2),1)) -> 2 | C48: =AVERAGEIF(Data_autos!$S:$S,DATE(LEFT(A48,4),MID(A48,6,2),1),Data_autos!$F:$F) -> 18938963
A49: 2024-10 | B49: =COUNTIF(Data_autos!$S:$S,DATE(LEFT(A49,4),MID(A49,6,2),1)) -> 2 | C49: =AVERAGEIF(Data_autos!$S:$S,DATE(LEFT(A49,4),MID(A49,6,2),1),Data_autos!$F:$F) -> 10016668
A50: 2025-03 | B50: =COUNTIF(Data_autos!$S:$S,DATE(LEFT(A50,4),MID(A50,6,2),1)) -> 2 | C50: =AVERAGEIF(Data_autos!$S:$S,DATE(LEFT(A50,4),MID(A50,6,2),1),Data_autos!$F:$F) -> 15550583
...

Sheet Dashboard
A1: Dashboard – Feria del Automóvil: Análisis de Ventas y Ofertas
A3: 👉 Aquí se insertarán las Tablas y Gráficos Dinámicos vinculados a la hoja 'Data_autos'
M4: % con financiación
M5: =[1]Analisis!F21 -> 0.5
G12: Cuenta de ID_Auto | H12: Etiquetas de columna
G13: Etiquetas de fila | H13: Excelente | I13: Seminuevo | J13: Usado | K13: Total general
G14: Buenos Aires | H14: 2 | J14: 2 | K14: 4
G15: Córdoba | H15: 2 | I15: 4 | K15: 6
G16: Entre Ríos | H16: 4 | J16: 2 | K16: 6
A17: Etiquetas de fila | B17: Cuenta de ID_Auto | G17: Mendoza | H17: 2 | I17: 4 | J17: 6 | K17: 12
A18: Chevrolet | B18: 2 | G18: Santa Fe | H18: 2 | I18: 6 | J18: 4 | K18: 12
A19: Citroën | B19: 2 | G19: Total general | H19: 12 | I19: 14 | J19: 14 | K19: 40
A20: Fiat | B20: 4
A21: Ford | B21: 6
A22: Honda | B22: 6
A23: Peugeot | B23: 8
A24: Renault | B24: 6
A25: Toyota | B25: 2
A26: Volkswagen | B26: 4
A27: Total general | B27: 40
A33: Etiquetas de fila | B33: Cuenta de ID_Auto
A34: No | B34: 20
A35: Sí | B35: 20
A36: Total general | B36: 40
G40: Etiquetas de fila | H40: Cuenta de ID_Auto
G41: Diésel | H41: 8
G42: Híbrido | H42: 16
G43: Nafta | H43: 16
G44: Total general | H44: 40
A51: ¿Cómo varía el precio promedio de los vehículos según la provincia y el tipo de combustible?
A62: Promedio de Precio_USD | B62: Etiquetas de columna
A63: Etiquetas de fila | B63: Diésel | C63: Híbrido | D63: Nafta | E63: Total general
A64: Buenos Aires | B64: 9106.0618 | D64: 17217.239 | E64: 13161.65
A65: Córdoba | C65: 21125.076 | D65: 16663.996 | E65: 18151.023
A66: Entre Ríos | B66: 19193.998 | C66: 19378.953 | E66: 19255.65
A67: Mendoza | C67: 12664.369 | D67: 13712.183 | E67: 13013.64
A68: Santa Fe | B68: 18471.994 | C68: 9740.7182 | D68: 12826.34 | E68: 12738.742
A69: Total general | B69: 16491.513 | C69: 13830.368 | D69: 14556.077 | E69: 14652.881
A71: Etiquetas de fila | B71: Promedio de Precio_USD | C71: Cantidad de publicaciones
A72: Alto | B72: 9106.0618 | C72: 2 | F72: ¿Cuál es el perfil típico de los vehículos con mayor precio promedio en el mercado (marca, año, km, origen y financiación)?
...
